Workbook
Name Slicer_Category: #N/A
Name Slicer_City: #N/A
Name Slicer_Customer_Segment: #N/A
Name Slicer_WEEKDAYS: #N/A

Sheet Sheet2
A1: Order_ID | B1: Order_Date | C1: Customer_Name | D1: Customer_Type | E1: Customer_Segment | F1: City | G1: Pincode | H1: Payment_Method | I1: SKU | J1: Product_Name | K1: Category | L1: Qty | M1: Price | N1: Discount | O1: Subtotal | P1: Tax | Q1: Delivery_Fee | R1: Surge_Fee | S1: Sales | T1: Delivery_Time | U1: WEEKDAYS
A2: O0001 | B2: 08-02-2025 | C2: Cust_0 | D2: Bulk | E2: Bakery | F2: Mumbai | G2: 532498 | H2: Wallet | I2: SKU0 | J2: Product_0 | K2: Veg | L2: 2 | M2: 94.25 | N2: 9.43 | O2: 179.07 | P2: 8.95 | Q2: 0 | R2: 10 | S2: 198.02 | T2: 12 | U2: =TEXT(B2,"dddd") -> Saturday
A3: O0002 | B3: 21-02-2025 | C3: Cust_1 | D3: Bulk | E3: Bakery | F3: Mumbai | G3: 157545 | H3: Upi | I3: SKU1 | J3: Product_1 | K3: Essentials | L3: 1 | M3: 18.45 | N3: 1.84 | O3: 16.61 | P3: 0.83 | Q3: 0 | R3: 0 | S3: 17.44 | T3: 24.67 | U3: =TEXT(B3,"dddd") -> Friday | W3: countblank (CITY) | X3: =COUNTBLANK(F2:F1499) -> 0
A4: O0005 | B4: 12-02-2025 | C4: Cust_4 | D4: Bulk | E4: Bakery | F4: Bangalore | G4: 429670 | H4: Upi | I4: SKU4 | J4: Product_4 | K4: Snacks | L4: 6 | M4: 52.47 | N4: 7.87 | O4: 306.95 | P4: 15.35 | Q4: 0 | R4: 0 | S4: 322.3 | T4: 23 | U4: =TEXT(B4,"dddd") -> Wednesday | X4: =28/1499 -> 0.018679119
A5: O0006 | B5: 08-01-2025 | C5: Cust_5 | D5: Bulk | E5: Café | F5: Delhi | G5: 258768 | H5: Netbanking | I5: SKU5 | J5: Product_5 | K5: Other | L5: 5 | M5: 78.11 | N5: 3.91 | O5: 386.64 | P5: 19.33 | Q5: 30 | R5: 15 | S5: 450.97 | T5: 18 | U5: =TEXT(B5,"dddd") -> Wednesday | W5: AVERAGE | X5: =AVERAGE(T:T) -> 24.671215
A6: O0007 | B6: 21-01-2025 | C6: Cust_6 | D6: Bulk | E6: Bakery | F6: Bangalore | G6: 776926 | H6: Upi | I6: SKU6 | J6: Product_6 | K6: Bakery | L6: 1 | M6: 103.87 | N6: 5.19 | O6: 98.68 | P6: 4.93 | Q6: 20 | R6: 0 | S6: 123.61 | T6: 13 | U6: =TEXT(B6,"dddd") -> Tuesday
A7: O0008 | B7: 08-02-2025 | C7: Cust_7 | D7: Bulk | E7: Bakery | F7: Delhi | G7: 233554 | H7: Cod | I7: SKU7 | J7: Product_7 | K7: Frozen | L7: 3 | M7: 129.5 | N7: 12.95 | O7: 375.55 | P7: 18.78 | Q7: 20 | R7: 10 | S7: 424.33 | T7: 16 | U7: =TEXT(B7,"dddd") -> Saturday
A8: O0009 | B8: 27-02-2025 | C8: Cust_8 | D8: Bulk | E8: Office | F8: Mumbai | G8: 159676 | H8: Upi | I8: SKU8 | J8: Product_8 | K8: Snacks | L8: 1 | M8: 131.89 | N8: 0 | O8: 131.89 | P8: 6.59 | Q8: 10 | R8: 0 | S8: 148.48 | T8: 23 | U8: =TEXT(B8,"dddd") -> Thursday
A9: O0010 | B9: 19-01-2025 | C9: Cust_9 | D9: Bulk | E9: Cloud Kitchen | F9: Delhi | G9: 688365 | H9: Upi | I9: SKU9 | J9: Product_9 | K9: Dairy | L9: 1 | M9: 207.92 | N9: 20.79 | O9: 187.13 | P9: 9.36 | Q9: 30 | R9: 0 | S9: 226.49 | T9: 17 | U9: =TEXT(B9,"dddd") -> Sunday
A10: O0011 | B10: 23-01-2025 | C10: Cust_10 | D10: New | E10: Household | F10: Delhi | G10: 481915 | H10: Wallet | I10: SKU10 | J10: Product_10 | K10: Dairy | L10: 3 | M10: 134.09 | N10: 13.41 | O10: 388.86 | P10: 19.44 | Q10: 20 | R10: 0 | S10: 428.3 | T10: 24.67 | U10: =TEXT(B10,"dddd") -> Thursday
A11: O0012 | B11: 11-01-2025 | C11: Cust_11 | D11: Bulk | E11: Cloud Kitchen | F11: Delhi | G11: 951587 | H11: Upi | I11: SKU11 | J11: Product_11 | K11: Fruits | L11: 6 | M11: 86.17 | N11: 0 | O11: 517.02 | P11: 25.85 | Q11: 10 | R11: 5 | S11: 557.87 | T11: 10 | U11: =TEXT(B11,"dddd") -> Saturday
A12: O0013 | B12: 11-01-2025 | C12: Cust_12 | D12: Bulk | E12: Cloud Kitchen | F12: Mumbai | G12: 962061 | H12: Upi | I12: SKU12 | J12: Product_12 | K12: Frozen | L12: 3 | M12: 104.71 | N12: 5.24 | O12: 308.89 | P12: 15.44 | Q12: 10 | R12: 20 | S12: 354.33 | T12: 16 | U12: =TEXT(B12,"dddd") -> Saturday
A13: O0014 | B13: 24-01-2025 | C13: Cust_13 | D13: Bulk | E13: Office | F13: Mumbai | G13: 730235 | H13: Card | I13: SKU13 | J13: Product_13 | K13: Baby | L13: 4 | M13: 204.9 | N13: 20.49 | O13: 799.11 | P13: 39.96 | Q13: 0 | R13: 0 | S13: 839.07 | T13: 24.67 | U13: =TEXT(B13,"dddd") -> Friday
A14: O0015 | B14: 22-02-2025 | C14: Cust_14 | D14: Returning | E14: Household | F14: Mumbai | G14: 605815 | H14: Upi | I14: SKU14 | J14: Product_14 | K14: Bakery | L14: 3 | M14: 193.33 | N14: 0 | O14: 579.99 | P14: 29 | Q14: 30 | R14: 20 | S14: 658.99 | T14: 3 | U14: =TEXT(B14,"dddd") -> Saturday
A15: O0016 | B15: 05-02-2025 | C15: Cust_15 | D15: Bulk | E15: Tea Stall | F15: Bangalore | G15: 434402 | H15: Wallet | I15: SKU15 | J15: Product_15 | K15: Fruits | L15: 3 | M15: 35.35 | N15: 3.54 | O15: 102.51 | P15: 5.13 | Q15: 30 | R15: 0 | S15: 137.64 | T15: 25 | U15: =TEXT(B15,"dddd") -> Wednesday
A16: O0017 | B16: 09-02-2025 | C16: Cust_16 | D16: Bulk | E16: Tea Stall | F16: Delhi | G16: 427073 | H16: Cod | I16: SKU16 | J16: Product_16 | K16: Snacks | L16: 2 | M16: 128.59 | N16: 6.43 | O16: 250.75 | P16: 12.54 | Q16: 0 | R16: 5 | S16: 268.29 | T16: 34 | U16: =TEXT(B16,"dddd") -> Sunday
A17: O0018 | B17: 24-01-2025 | C17: Cust_17 | D17: Bulk | E17: Tea Stall | F17: Mumbai | G17: 416915 | H17: Upi | I17: SKU17 | J17: Product_17 | K17: Baby | L17: 5 | M17: 145.22 | N17: 7.26 | O17: 718.84 | P17: 35.94 | Q17: 20 | R17: 5 | S17: 779.78 | T17: 24.67 | U17: =TEXT(B17,"dddd") -> Friday
A18: O0019 | B18: 03-01-2025 | C18: Cust_18 | D18: Bulk | E18: Bakery | F18: Bangalore | G18: 890857 | H18: Phonepe | I18: SKU18 | J18: Product_18 | K18: Essentials | L18: 1 | M18: 156.96 | N18: 23.54 | O18: 133.42 | P18: 6.67 | Q18: 10 | R18: 5 | S18: 155.09 | T18: 18 | U18: =TEXT(B18,"dddd") -> Friday
A19: O0020 | B19: 22-01-2025 | C19: Cust_19 | D19: Bulk | E19: Office | F19: Bangalore | H19: Upi | I19: SKU19 | J19: Product_19 | K19: Essentials | L19: 2 | M19: 19.81 | N19: 0 | O19: 39.62 | P19: 1.98 | Q19: 20 | R19: 20 | S19: 81.6 | T19: 42 | U19: =TEXT(B19,"dddd") -> Wednesday
A20: O0021 | B20: 22-02-2025 | C20: Cust_20 | D20: Bulk | E20: Café | F20: Mumbai | G20: 727433 | H20: Upi | I20: SKU20 | J20: Product_20 | K20: Beverages | L20: 3 | M20: 164.88 | N20: 16.49 | O20: 478.15 | P20: 23.91 | Q20: 30 | R20: 10 | S20: 542.06 | T20: 24.67 | U20: =TEXT(B20,"dddd") -> Saturday
A21: O0022 | B21: 02-01-2025 | C21: Cust_21 | D21: Bulk | E21: Bakery | F21: Bangalore | G21: 756639 | H21: Upi | I21: SKU21 | J21: Product_21 | K21: Beverages | L21: 2 | M21: 185.31 | N21: 27.8 | O21: 342.82 | P21: 17.14 | Q21: 10 | R21: 0 | S21: 369.96 | T21: 32 | U21: =TEXT(B21,"dddd") -> Thursday
A22: O0023 | B22: 24-01-2025 | C22: Cust_22 | D22: Bulk | E22: Café | F22: Delhi | G22: 881817 | H22: Netbanking | I22: SKU22 | J22: Product_22 | K22: Veg | L22: 1 | M22: 4.92 | N22: 0.25 | O22: 4.67 | P22: 0.23 | Q22: 10 | R22: 15 | S22: 29.9 | T22: 41 | U22: =TEXT(B22,"dddd") -> Friday
A23: O0024 | B23: 13-02-2025 | C23: Cust_23 | D23: Bulk | E23: Bakery | F23: Bangalore | G23: 607606 | H23: Upi | I23: SKU23 | J23: Product_23 | K23: Fruits | L23: 1 | M23: 143.95 | N23: 7.2 | O23: 136.75 | P23: 6.84 | Q23: 30 | R23: 5 | S23: 178.59 | T23: 27 | U23: =TEXT(B23,"dddd") -> Thursday
A24: O0025 | B24: 30-01-2025 | C24: Cust_24 | D24: New | E24: Household | F24: Bangalore | G24: 127856 | H24: Gpay | I24: SKU24 | J24: Product_24 | K24: Beverages | L24: 3 | M24: 99.86 | N24: 14.98 | O24: 284.6 | P24: 14.23 | Q24: 20 | R24: 5 | S24: 323.83 | T24: 38 | U24: =TEXT(B24,"dddd") -> Thursday
A25: O0026 | B25: 07-02-2025 | C25: Cust_25 | D25: Bulk | E25: Office | F25: Delhi | G25: 248757 | H25: Upi | I25: SKU25 | J25: Product_25 | K25: Baby | L25: 3 | M25: 17.39 | N25: 0 | O25: 52.17 | P25: 2.61 | Q25: 0 | R25: 10 | S25: 64.78 | T25: 11 | U25: =TEXT(B25,"dddd") -> Friday
A26: O0027 | B26: 02-01-2025 | C26: Cust_26 | D26: Bulk | E26: Tea Stall | F26: Mumbai | G26: 436676 | H26: Upi | I26: SKU26 | J26: Product_26 | K26: Beverages | L26: 2 | M26: 42.69 | N26: 0 | O26: 85.38 | P26: 4.27 | Q26: 10 | R26: 15 | S26: 114.65 | T26: 26 | U26: =TEXT(B26,"dddd") -> Thursday
A27: O0028 | B27: 01-03-2025 | C27: Cust_27 | D27: Bulk | E27: Bakery | F27: Mumbai | G27: 752665 | H27: Upi | I27: SKU27 | J27: Product_27 | K27: Essentials | L27: 3 | M27: 61.3 | N27: 0 | O27: 183.9 | P27: 9.19 | Q27: 30 | R27: 15 | S27: 238.09 | T27: 45 | U27: =TEXT(B27,"dddd") -> Saturday
A28: O0029 | B28: 21-01-2025 | C28: Cust_28 | D28: Bulk | E28: Office | F28: Bangalore | G28: 816756 | H28: Upi | I28: SKU28 | J28: Product_28 | K28: Fruits | L28: 4 | M28: 86.32 | N28: 4.32 | O28: 340.96 | P28: 17.05 | Q28: 0 | R28: 0 | S28: 358.01 | T28: 28 | U28: =TEXT(B28,"dddd") -> Tuesday
A29: O0030 | B29: 02-02-2025 | C29: Cust_29 | D29: Bulk | E29: Tea Stall | F29: Delhi | G29: 672212 | H29: Phonepe | I29: SKU29 | J29: Product_29 | K29: Fruits | L29: 1 | M29: 65.42 | N29: 6.54 | O29: 58.88 | P29: 2.94 | Q29: 0 | R29: 5 | S29: 66.82 | T29: 41 | U29: =TEXT(B29,"dddd") -> Sunday
A30: O0031 | B30: 12-01-2025 | C30: Cust_30 | D30: Returning | E30: Household | F30: Bangalore | G30: 791757 | H30: Cod | I30: SKU30 | J30: Product_30 | K30: Veg | L30: 6 | M30: 9.55 | N30: 1.43 | O30: 55.87 | P30: 2.79 | Q30: 20 | R30: 10 | S30: 88.66 | T30: 12 | U30: =TEXT(B30,"dddd") -> Sunday
A31: O0032 | B31: 27-02-2025 | C31: Cust_31 | D31: Bulk | E31: Cloud Kitchen | F31: Bangalore | G31: 322320 | H31: Phonepe | I31: SKU31 | J31: Product_31 | K31: Dairy | L31: 2 | M31: 131.91 | N31: 13.19 | O31: 250.63 | P31: 12.53 | Q31: 0 | R31: 15 | S31: 278.16 | T31: 22 | U31: =TEXT(B31,"dddd") -> Thursday
... A57: O0058 | B57: 04-01-2025 | C57: Cust_57 | D57: Bulk | E57: Café | F57: Delhi | G57: 963561 | H57: Card | I57: SKU57 | J57: Product_57 | K57: Fruits | L57: 3 | M57: 190.03 | N57: 0 | O57: 570.09 | P57: 28.5 | Q57: 10 | R57: 20 | S57: 628.59 | T57: 41 | U57: =TEXT(B57,"dddd") -> Saturday
A58: O0059 | B58: 25-01-2025 | C58: Cust_58 | D58: Bulk | E58: Tea Stall | F58: Bangalore | H58: Card | I58: SKU58 | J58: Product_58 | K58: Frozen | L58: 2 | M58: 89.93 | N58: 4.5 | O58: 175.36 | P58: 8.77 | Q58: 10 | R58: 20 | S58: 214.13 | T58: 30 | U58: =TEXT(B58,"dddd") -> Saturday
A59: O0060 | B59: 01-03-2025 | C59: Cust_59 | D59: Bulk | E59: Office | F59: Mumbai | G59: 249369 | H59: Wallet | I59: SKU59 | J59: Product_59 | K59: Snacks | L59: 5 | M59: 125.79 | N59: 0 | O59: 628.95 | P59: 31.45 | Q59: 30 | R59: 10 | S59: 700.4 | T59: 10 | U59: =TEXT(B59,"dddd") -> Saturday
A60: O0061 | B60: 14-01-2025 | C60: Cust_60 | D60: Bulk | E60: Café | F60: Bangalore | G60: 474999 | H60: Card | I60: SKU60 | J60: Product_60 | K60: Frozen | L60: 1 | M60: 130.64 | N60: 0 | O60: 130.64 | P60: 6.53 | Q60: 10 | R60: 5 | S60: 152.17 | T60: 32 | U60: =TEXT(B60,"dddd") -> Tuesday
A61: O0062 | B61: 19-02-2025 | C61: Cust_61 | D61: Bulk | E61: Office | F61: Delhi | G61: 893719 | H61: Wallet | I61: SKU61 | J61: Product_61 | K61: Dairy | L61: 5 | M61: 114.77 | N61: 17.22 | O61: 556.63 | P61: 27.83 | Q61: 0 | R61: 15 | S61: 599.46 | T61: 34 | U61: =TEXT(B61,"dddd") -> Wednesday
A62: O0063 | B62: 27-02-2025 | C62: Cust_62 | D62: Bulk | E62: Cloud Kitchen | F62: Mumbai | G62: 426916 | H62: Netbanking | I62: SKU62 | J62: Product_62 | K62: Veg | L62: 1 | M62: 67.3 | N62: 3.37 | O62: 63.93 | P62: 3.2 | Q62: 10 | R62: 20 | S62: 97.13 | T62: 30 | U62: =TEXT(B62,"dddd") -> Thursday
A63: O0064 | B63: 09-01-2025 | C63: Cust_63 | D63: Bulk | E63: Tea Stall | F63: Mumbai | G63: 658030 | H63: Card | I63: SKU63 | J63: Product_63 | K63: Veg | L63: 5 | M63: 65.64 | N63: 0 | O63: 328.2 | P63: 16.41 | Q63: 0 | R63: 0 | S63: 344.61 | T63: 34 | U63: =TEXT(B63,"dddd") -> Thursday
A64: O0065 | B64: 26-01-2025 | C64: Cust_64 | D64: Bulk | E64: Tea Stall | F64: Bangalore | G64: 972388 | H64: Upi | I64: SKU64 | J64: Product_64 | K64: Dairy | L64: 3 | M64: 82.14 | N64: 12.32 | O64: 234.1 | P64: 11.71 | Q64: 0 | R64: 0 | S64: 245.81 | T64: 31 | U64: =TEXT(B64,"dddd") -> Sunday
A65: O0066 | B65: 22-02-2025 | C65: Cust_65 | D65: Bulk | E65: Office | F65: Mumbai | G65: 228322 | H65: Netbanking | I65: SKU65 | J65: Product_65 | K65: Fruits | L65: 1 | M65: 122.6 | N65: 0 | O65: 122.6 | P65: 6.13 | Q65: 10 | R65: 10 | S65: 148.73 | T65: 35 | U65: =TEXT(B65,"dddd") -> Saturday
...

Sheet KPI
A1: TOTAL SALES | B1: =SUM(Sheet2!S2:S1499) -> 563284.75 | C1: SUM
A2: TOTAL PRODUCTS | B2: =COUNTA(_xlfn.UNIQUE(Sheet2!J2:J1499)) -> 200 | C2: COUNT UNIQUE
A3: TOTAL SKU'S | B3: =COUNTA(_xlfn.UNIQUE(Sheet2!I2:I1499)) -> 200 | C3: COUNT UNIQUE
A4: TOTAL ORDERS | B4: =COUNTA(_xlfn.UNIQUE(Sheet2!A2:A1499)) -> 1498 | C4: COUNTA
A5: AVG DELIVERY TIME | B5: =AVERAGE(Sheet2!T2:T1499) -> 24.671215 | C5: AVERAGE

Sheet CHARTS
A1: CREATE A CHART TO SHOW THE SALES OVER DIFFERENT WEEKDAYS
A3: Row Labels | B3: Sum of Sales
A4: Sunday | B4: 89688.34
A5: Monday | B5: 63297.72
A6: Tuesday | B6: 69215.7
A7: Wednesday | B7: 89028.19
A8: Thursday | B8: 91118.9
A9: Friday | B9: 75665.63
A10: Saturday | B10: 85270.27
A11: Grand Total | B11: 563284.75
A18: CREATE A CHART TO SHOW TOP 10 PRODUCTS
A20: Row Labels | B20: Sum of Sales
A21: Product_102 | B21: 4361.11
A22: Product_12 | B22: 4753.83
A23: Product_13 | B23: 4338.5
A24: Product_139 | B24: 5111.6
A25: Product_160 | B25: 4726.73
A26: Product_18 | B26: 4194.36
A27: Product_198 | B27: 4337.62
A28: Product_30 | B28: 5188.17
A29: Product_84 | B29: 4399.39
A30: Product_85 | B30: 4295.97
A31: Grand Total | B31: 45707.28
A37: CREATE A CHART TO SHOW | C37: BOTTOM 1O SKU'S
A40: Row Labels | B40: Sum of Sales
A41: SKU104 | B41: 1447.2
A42: SKU107 | B42: 1531.74
A43: SKU119 | B43: 1531.49
A44: SKU135 | B44: 1108.3
A45: SKU151 | B45: 1529.18
A46: SKU168 | B46: 1113.35
A47: SKU186 | B47: 1316.78
A48: SKU188 | B48: 1413.18
A49: SKU189 | B49: 1294.92
A50: SKU42 | B50: 1469.34
A51: Grand Total | B51: 13755.48
A57: CREATE A CHART TO SHOW THE CONTRIBUTION OF SALES BY EACH CITY
A59: Row Labels | B59: Sum of Sales
A60: Bangalore | B60: 201528.98
A61: Delhi | B61: 180200.31
...

Sheet REPORTS
